Workbook

Sheet Tablas
A2: Inventario de tablas
A4: Módulo | B4: Tabla | C4: Propósito y reglas documentadas | D4: Campos | E4: Clave primaria | F4: FK salientes | G4: Tipos pendientes | H4: Observaciones
A5: Académico | B5: alumnos_mallas_raanariba | C5: Inscripcion del alumno a un plan. Admite varias carreras o cambios de plan conservando historial. | D5: =COUNTIFS(Campos!$B$5:$B$224,B5) -> 6 | E5: alumnos_mallas_id | F5: =COUNTIFS(Relaciones!$C$7:$C$52,B5) -> 2 | G5: =COUNTIFS(Campos!$B$5:$B$224,B5,Campos!$E$5:$E$224,"Pendiente") -> 0
A6: Académico | B6: asignaturas_raanariba | C6: Catálogo común de asignaturas que pueden compartir varias mallas. | D6: =COUNTIFS(Campos!$B$5:$B$224,B6) -> 5 | E6: asignaturas_id | F6: =COUNTIFS(Relaciones!$C$7:$C$52,B6) -> 0 | G6: =COUNTIFS(Campos!$B$5:$B$224,B6,Campos!$E$5:$E$224,"Pendiente") -> 0
A7: Académico | B7: aulas_raanariba | C7: Catálogo de aulas y su capacidad. | D7: =COUNTIFS(Campos!$B$5:$B$224,B7) -> 3 | E7: aulas_id | F7: =COUNTIFS(Relaciones!$C$7:$C$52,B7) -> 0 | G7: =COUNTIFS(Campos!$B$5:$B$224,B7,Campos!$E$5:$E$224,"Pendiente") -> 0
A8: Académico | B8: carreras_raanariba | C8: Programa academico. Una carrera tiene varias versiones de malla curricular. | D8: =COUNTIFS(Campos!$B$5:$B$224,B8) -> 6 | E8: carreras_id | F8: =COUNTIFS(Relaciones!$C$7:$C$52,B8) -> 0 | G8: =COUNTIFS(Campos!$B$5:$B$224,B8,Campos!$E$5:$E$224,"Pendiente") -> 0
A9: Académico | B9: docentes_secciones_raanariba | C9: Asignacion docente N:M a secciones, admite codocencia. | D9: =COUNTIFS(Campos!$B$5:$B$224,B9) -> 5 | E9: docentes_secciones_id | F9: =COUNTIFS(Relaciones!$C$7:$C$52,B9) -> 2 | G9: =COUNTIFS(Campos!$B$5:$B$224,B9,Campos!$E$5:$E$224,"Pendiente") -> 0
A10: Académico | B10: horarios_raanariba | C10: Días y horas de cada sección. | D10: =COUNTIFS(Campos!$B$5:$B$224,B10) -> 5 | E10: horarios_id | F10: =COUNTIFS(Relaciones!$C$7:$C$52,B10) -> 1 | G10: =COUNTIFS(Campos!$B$5:$B$224,B10,Campos!$E$5:$E$224,"Pendiente") -> 0
A11: Académico | B11: mallas_asignaturas_raanariba | C11: Tabla puente N:M. Una misma asignatura se comparte por varias mallas/carreras, sin duplicar su definicion ni sus unidades valorativas. | D11: =COUNTIFS(Campos!$B$5:$B$224,B11) -> 5 | E11: mallas_asignaturas_id | F11: =COUNTIFS(Relaciones!$C$7:$C$52,B11) -> 2 | G11: =COUNTIFS(Campos!$B$5:$B$224,B11,Campos!$E$5:$E$224,"Pendiente") -> 0 | H11: plan en desgaste
A12: Académico | B12: mallas_curriculares_raanariba | C12: Plan de estudios versionado que pertenece a exactamente una carrera. | D12: =COUNTIFS(Campos!$B$5:$B$224,B12) -> 8 | E12: mallas_curriculares_id | F12: =COUNTIFS(Relaciones!$C$7:$C$52,B12) -> 1 | G12: =COUNTIFS(Campos!$B$5:$B$224,B12,Campos!$E$5:$E$224,"Pendiente") -> 0
A13: Académico | B13: matriculas_raanariba | C13: Validar que alumnos_mallas y mallas_asignaturas pertenecen a la misma malla, y que secciones.asignaturas_id coincide con la asignatura del plan. Una matricula activa por alumno y seccion incluso entre planes. cargas_entrada nullable para captura directa; no contar intentos rechazados como matriculas. | D13: =COUNTIFS(Campos!$B$5:$B$224,B13) -> 7 | E13: matriculas_id | F13: =COUNTIFS(Relaciones!$C$7:$C$52,B13) -> 4 | G13: =COUNTIFS(Campos!$B$5:$B$224,B13,Campos!$E$5:$E$224,"Pendiente") -> 1
A14: Académico | B14: periodos_academicos_raanariba | C14: Calendario de períodos académicos. | D14: =COUNTIFS(Campos!$B$5:$B$224,B14) -> 4 | E14: periodos_academicos_id | F14: =COUNTIFS(Relaciones!$C$7:$C$52,B14) -> 0 | G14: =COUNTIFS(Campos!$B$5:$B$224,B14,Campos!$E$5:$E$224,"Pendiente") -> 0
A15: Académico | B15: secciones_raanariba | C15: Oferta de una asignatura en un período, aula y cupo. | D15: =COUNTIFS(Campos!$B$5:$B$224,B15) -> 7 | E15: secciones_id | F15: =COUNTIFS(Relaciones!$C$7:$C$52,B15) -> 3 | G15: =COUNTIFS(Campos!$B$5:$B$224,B15,Campos!$E$5:$E$224,"Pendiente") -> 0
A16: Auditoría | B16: auditoria_eventos_raanariba | C16: Historial de cambios de datos y valores anteriores/nuevos. | D16: =COUNTIFS(Campos!$B$5:$B$224,B16) -> 11 | E16: auditoria_eventos_id | F16: =COUNTIFS(Relaciones!$C$7:$C$52,B16) -> 2 | G16: =COUNTIFS(Campos!$B$5:$B$224,B16,Campos!$E$5:$E$224,"Pendiente") -> 3
A17: Auditoría | B17: bitacora_operaciones_raanariba | C17: Seguimiento de operaciones y sus resultados. | D17: =COUNTIFS(Campos!$B$5:$B$224,B17) -> 10 | E17: bitacora_operaciones_id | F17: =COUNTIFS(Relaciones!$C$7:$C$52,B17) -> 2 | G17: =COUNTIFS(Campos!$B$5:$B$224,B17,Campos!$E$5:$E$224,"Pendiente") -> 2
A18: Auditoría | B18: eliminaciones_log_raanariba | C18: Evidencia de eliminaciones y restauraciones. | D18: =COUNTIFS(Campos!$B$5:$B$224,B18) -> 12 | E18: eliminaciones_log_id | F18: =COUNTIFS(Relaciones!$C$7:$C$52,B18) -> 2 | G18: =COUNTIFS(Campos!$B$5:$B$224,B18,Campos!$E$5:$E$224,"Pendiente") -> 3
A19: Auditoría | B19: logs_sistema_raanariba | C19: Eventos técnicos del sistema. | D19: =COUNTIFS(Campos!$B$5:$B$224,B19) -> 10 | E19: logs_sistema_id | F19: =COUNTIFS(Relaciones!$C$7:$C$52,B19) -> 2 | G19: =COUNTIFS(Campos!$B$5:$B$224,B19,Campos!$E$5:$E$224,"Pendiente") -> 2
A20: Data Entry | B20: cargas_entrada_raanariba | C20: Data Entry por carga: recepcion, validacion y publicacion de registros aceptados. Reporteria consulta los datos academicos aceptados; los rechazos permanecen en validaciones_entrada. | D20: =COUNTIFS(Campos!$B$5:$B$224,B20) -> 9 | E20: cargas_entrada_id | F20: =COUNTIFS(Relaciones!$C$7:$C$52,B20) -> 1 | G20: =COUNTIFS(Campos!$B$5:$B$224,B20,Campos!$E$5:$E$224,"Pendiente") -> 2
A21: Data Entry | B21: validaciones_entrada_raanariba | C21: Errores de validación por carga, fila y campo. | D21: =COUNTIFS(Campos!$B$5:$B$224,B21) -> 7 | E21: validaciones_entrada_id | F21: =COUNTIFS(Relaciones!$C$7:$C$52,B21) -> 1 | G21: =COUNTIFS(Campos!$B$5:$B$224,B21,Campos!$E$5:$E$224,"Pendiente") -> 1
A22: Estadísticas | B22: indicadores_estadisticos_raanariba | C22: Catalogo de metricas y su regla de agregacion. Ejemplos: matriculados, docentes asignados y porcentaje de ocupacion. Porcentajes deben calcularse desde sus bases, no sumarse. | D22: =COUNTIFS(Campos!$B$5:$B$224,B22) -> 7 | E22: indicadores_estadisticos_id | F22: =COUNTIFS(Relaciones!$C$7:$C$52,B22) -> 0 | G22: =COUNTIFS(Campos!$B$5:$B$224,B22,Campos!$E$5:$E$224,"Pendiente") -> 0
A23: Estadísticas | B23: reportes_definiciones_raanariba | C23: Catalogo de reportes estadisticos; su contenido se define con reportes_indicadores, y sus resultados numericos en resultados_estadisticos. | D23: =COUNTIFS(Campos!$B$5:$B$224,B23) -> 5 | E23: reportes_definiciones_id | F23: =COUNTIFS(Relaciones!$C$7:$C$52,B23) -> 0 | G23: =COUNTIFS(Campos!$B$5:$B$224,B23,Campos!$E$5:$E$224,"Pendiente") -> 0
... A38: Seguridad RBAC | B38: usuarios_roles_raanariba | C38: Asignación de varios roles de acceso a un usuario. | D38: =COUNTIFS(Campos!$B$5:$B$224,B38) -> 3 | E38: usuarios_roles_id | F38: =COUNTIFS(Relaciones!$C$7:$C$52,B38) -> 2 | G38: =COUNTIFS(Campos!$B$5:$B$224,B38,Campos!$E$5:$E$224,"Pendiente") -> 0

Sheet Campos
A2: Diccionario de campos
A4: Módulo | B4: Tabla | C4: Orden | D4: Campo | E4: Tipo en modelo | F4: Tipo previsto | G4: Obligatorio | H4: PK | I4: FK | J4: Restricciones UK | K4: Referencia FK | L4: Descripción contextual
A5: Académico | B5: alumnos_mallas_raanariba | C5: 1 | D5: alumnos_mallas_id | E5: NUMBER(12) | F5: NUMBER(12) | G5: Sí | H5: Sí | I5: No | L5: Inscripción del alumno a una malla curricular.
A6: Académico | B6: alumnos_mallas_raanariba | C6: 2 | D6: alumnos_id | E6: NUMBER(12) | F6: NUMBER(12) | G6: Sí | H6: No | I6: Sí | J6: uk_alumnos_mallas_1 | K6: alumnos_raanariba.alumnos_id | L6: Referencia a alumnos_raanariba.alumnos_id.
A7: Académico | B7: alumnos_mallas_raanariba | C7: 3 | D7: mallas_curriculares_id | E7: NUMBER(12) | F7: NUMBER(12) | G7: Sí | H7: No | I7: Sí | J7: uk_alumnos_mallas_1 | K7: mallas_curriculares_raanariba.mallas_curriculares_id | L7: Referencia a mallas_curriculares_raanariba.mallas_curriculares_id.
A8: Académico | B8: alumnos_mallas_raanariba | C8: 4 | D8: fecha_ingreso | E8: DATE | F8: DATE | G8: Sí | H8: No | I8: No | L8: Fecha de ingreso al ámbito de esta tabla.
A9: Académico | B9: alumnos_mallas_raanariba | C9: 5 | D9: fecha_egreso | E9: DATE | F9: DATE | G9: No | H9: No | I9: No | L9: Fecha egreso.
A10: Académico | B10: alumnos_mallas_raanariba | C10: 6 | D10: estado | E10: VARCHAR2(20 BYTE) | F10: VARCHAR2(20 BYTE) | G10: Sí | H10: No | I10: No | L10: Estado del registro en su ciclo de vida.
A11: Académico | B11: asignaturas_raanariba | C11: 1 | D11: asignaturas_id | E11: NUMBER(12) | F11: NUMBER(12) | G11: Sí | H11: Sí | I11: No | L11: Identificador único de asignaturas.
A12: Académico | B12: asignaturas_raanariba | C12: 2 | D12: codigo_asignatura | E12: VARCHAR2(30 BYTE) | F12: VARCHAR2(30 BYTE) | G12: Sí | H12: No | I12: No | J12: asignaturas_codigo_asignatura_uk | L12: Codigo asignatura.
A13: Académico | B13: asignaturas_raanariba | C13: 3 | D13: nombre_asignatura | E13: VARCHAR2(150 BYTE) | F13: VARCHAR2(150 BYTE) | G13: Sí | H13: No | I13: No | L13: Nombre asignatura.
A14: Académico | B14: asignaturas_raanariba | C14: 4 | D14: unidades_valorativas | E14: NUMBER(4,1) | F14: NUMBER(4,1) | G14: Sí | H14: No | I14: No | L14: Unidades valorativas.
A15: Académico | B15: asignaturas_raanariba | C15: 5 | D15: estado | E15: VARCHAR2(20 BYTE) | F15: VARCHAR2(20 BYTE) | G15: Sí | H15: No | I15: No | L15: Estado del registro en su ciclo de vida.
A16: Académico | B16: aulas_raanariba | C16: 1 | D16: aulas_id | E16: NUMBER(12) | F16: NUMBER(12) | G16: Sí | H16: Sí | I16: No | L16: Identificador único de aulas.
A17: Académico | B17: aulas_raanariba | C17: 2 | D17: codigo_aula | E17: VARCHAR2(30 BYTE) | F17: VARCHAR2(30 BYTE) | G17: Sí | H17: No | I17: No | J17: aulas_codigo_aula_uk | L17: Codigo aula.
A18: Académico | B18: aulas_raanariba | C18: 3 | D18: capacidad | E18: NUMBER(5) | F18: NUMBER(5) | G18: Sí | H18: No | I18: No | L18: Capacidad.
A19: Académico | B19: carreras_raanariba | C19: 1 | D19: carreras_id | E19: NUMBER(12) | F19: NUMBER(12) | G19: Sí | H19: Sí | I19: No | L19: Identificador único de carreras.
A20: Académico | B20: carreras_raanariba | C20: 2 | D20: codigo_carrera | E20: VARCHAR2(30 BYTE) | F20: VARCHAR2(30 BYTE) | G20: Sí | H20: No | I20: No | J20: uk_carreras_1 | L20: Codigo carrera.
A21: Académico | B21: carreras_raanariba | C21: 3 | D21: nombre_carrera | E21: VARCHAR2(200 BYTE) | F21: VARCHAR2(200 BYTE) | G21: Sí | H21: No | I21: No | L21: Nombre carrera.
A22: Académico | B22: carreras_raanariba | C22: 4 | D22: nivel_academico | E22: VARCHAR2(50 BYTE) | F22: VARCHAR2(50 BYTE) | G22: Sí | H22: No | I22: No | L22: Nivel academico.
A23: Académico | B23: carreras_raanariba | C23: 5 | D23: titulo_otorgado | E23: VARCHAR2(200 BYTE) | F23: VARCHAR2(200 BYTE) | G23: Sí | H23: No | I23: No | L23: Titulo otorgado.
A24: Académico | B24: carreras_raanariba | C24: 6 | D24: estado | E24: VARCHAR2(20 BYTE) | F24: VARCHAR2(20 BYTE) | G24: Sí | H24: No | I24: No | L24: Estado del registro en su ciclo de vida.
A25: Académico | B25: docentes_secciones_raanariba | C25: 1 | D25: docentes_secciones_id | E25: NUMBER(12) | F25: NUMBER(12) | G25: Sí | H25: Sí | I25: No | L25: Identificador único de docentes secciones.
A26: Académico | B26: docentes_secciones_raanariba | C26: 2 | D26: docentes_id | E26: NUMBER(12) | F26: NUMBER(12) | G26: Sí | H26: No | I26: Sí | J26: uk_docentes_seccione_1 | K26: docentes_raanariba.docentes_id | L26: Referencia a docentes_raanariba.docentes_id.
A27: Académico | B27: docentes_secciones_raanariba | C27: 3 | D27: secciones_id | E27: NUMBER(12) | F27: NUMBER(12) | G27: Sí | H27: No | I27: Sí | J27: uk_docentes_seccione_1 | K27: secciones_raanariba.secciones_id | L27: Referencia a secciones_raanariba.secciones_id.
A28: Académico | B28: docentes_secciones_raanariba | C28: 4 | D28: funcion_docente | E28: VARCHAR2(30 BYTE) | F28: VARCHAR2(30 BYTE) | G28: Sí | H28: No | I28: No | L28: Funcion docente.
A29: Académico | B29: docentes_secciones_raanariba | C29: 5 | D29: fecha_asignacion | E29: DATE | F29: DATE | G29: Sí | H29: No | I29: No | L29: Fecha asignacion.
A30: Académico | B30: horarios_raanariba | C30: 1 | D30: horarios_id | E30: NUMBER(12) | F30: NUMBER(12) | G30: Sí | H30: Sí | I30: No | L30: Identificador único de horarios.
A31: Académico | B31: horarios_raanariba | C31: 2 | D31: secciones_id | E31: NUMBER(12) | F31: NUMBER(12) | G31: Sí | H31: No | I31: Sí | K31: secciones_raanariba.secciones_id | L31: Referencia a secciones_raanariba.secciones_id.
A32: Académico | B32: horarios_raanariba | C32: 3 | D32: dia_semana | E32: NUMBER(1) | F32: NUMBER(1) | G32: Sí | H32: No | I32: No | L32: Dia semana.
A33: Académico | B33: horarios_raanariba | C33: 4 | D33: hora_inicio | E33: VARCHAR2(5 BYTE) | F33: VARCHAR2(5 BYTE) | G33: Sí | H33: No | I33: No | L33: Hora inicio.
A34: Académico | B34: horarios_raanariba | C34: 5 | D34: hora_fin | E34: VARCHAR2(5 BYTE) | F34: VARCHAR2(5 BYTE) | G34: Sí | H34: No | I34: No | L34: Hora fin.
A35: Académico | B35: mallas_asignaturas_raanariba | C35: 1 | D35: mallas_asignaturas_id | E35: NUMBER(12) | F35: NUMBER(12) | G35: Sí | H35: Sí | I35: No | L35: Asignatura dentro de una malla curricular.
A36: Académico | B36: mallas_asignaturas_raanariba | C36: 2 | D36: mallas_curriculares_id | E36: NUMBER(12) | F36: NUMBER(12) | G36: Sí | H36: No | I36: Sí | J36: uk_mallas_asignatura_1 | K36: mallas_curriculares_raanariba.mallas_curriculares_id | L36: Referencia a mallas_curriculares_raanariba.mallas_curriculares_id.
A37: Académico | B37: mallas_asignaturas_raanariba | C37: 3 | D37: asignaturas_id | E37: NUMBER(12) | F37: NUMBER(12) | G37: Sí | H37: No | I37: Sí | J37: uk_mallas_asignatura_1 | K37: asignaturas_raanariba.asignaturas_id | L37: Referencia a asignaturas_raanariba.asignaturas_id.
A38: Académico | B38: mallas_asignaturas_raanariba | C38: 4 | D38: nivel_sugerido | E38: NUMBER(3) | F38: NUMBER(3) | G38: Sí | H38: No | I38: No | L38: Nivel sugerido.
A39: Académico | B39: mallas_asignaturas_raanariba | C39: 5 | D39: tipo_asignatura | E39: VARCHAR2(20 BYTE) | F39: VARCHAR2(20 BYTE) | G39: Sí | H39: No | I39: No | L39: Tipo asignatura.
A40: Académico | B40: mallas_curriculares_raanariba | C40: 1 | D40: mallas_curriculares_id | E40: NUMBER(12) | F40: NUMBER(12) | G40: Sí | H40: Sí | I40: No | L40: Identificador único de mallas curriculares.
A41: Académico | B41: mallas_curriculares_raanariba | C41: 2 | D41: carreras_id | E41: NUMBER(12) | F41: NUMBER(12) | G41: Sí | H41: No | I41: Sí | J41: uk_mallas_curricular_2 | K41: carreras_raanariba.carreras_id | L41: Referencia a carreras_raanariba.carreras_id.
A42: Académico | B42: mallas_curriculares_raanariba | C42: 3 | D42: codigo_malla | E42: VARCHAR2(40 BYTE) | F42: VARCHAR2(40 BYTE) | G42: Sí | H42: No | I42: No | J42: uk_mallas_curricular_1 | L42: Codigo malla.
...

Sheet Relaciones
A2: Inventario de relaciones
A3: Esquema RAANARIBA. Fuente: RAANARIBA_Unificado_Ampliado.zip, modelo relacional.
A4: Padre = tabla referenciada. Hija = tabla que contiene la FK. NO ACTION impide borrar un padre que conserva referencias.
A6: Tabla padre | B6: Campo referenciado | C6: Tabla hija | D6: Campo FK | E6: Hijos por padre | F6: Padres por hijo | G6: FK opcional | H6: Al eliminar padre | I6: Nombre de FK
A7: alumnos_mallas_raanariba | B7: alumnos_mallas_id | C7: matriculas_raanariba | D7: alumnos_mallas_id | E7: 0..N | F7: 1 | G7: No | H7: NO ACTION | I7: fk_matriculas_25
A8: alumnos_raanariba | B8: alumnos_id | C8: alumnos_mallas_raanariba | D8: alumnos_id | E8: 0..N | F8: 1 | G8: No | H8: NO ACTION | I8: fk_alumnos_mallas_37
A9: asignaturas_raanariba | B9: asignaturas_id | C9: mallas_asignaturas_raanariba | D9: asignaturas_id | E9: 0..N | F9: 1 | G9: No | H9: NO ACTION | I9: fk_mallas_asignat_36
A10: asignaturas_raanariba | B10: asignaturas_id | C10: secciones_raanariba | D10: asignaturas_id | E10: 0..N | F10: 1 | G10: No | H10: NO ACTION | I10: fk_secciones_5
A11: aulas_raanariba | B11: aulas_id | C11: secciones_raanariba | D11: aulas_id | E11: 0..N | F11: 1 | G11: No | H11: NO ACTION | I11: fk_secciones_21
A12: cargas_entrada_raanariba | B12: cargas_entrada_id | C12: matriculas_raanariba | D12: cargas_entrada_id | E12: 0..N | F12: 0..1 | G12: Sí | H12: NO ACTION | I12: fk_matriculas_27
A13: cargas_entrada_raanariba | B13: cargas_entrada_id | C13: reportes_ejecuciones_raanariba | D13: cargas_entrada_id | E13: 0..N | F13: 0..1 | G13: Sí | H13: NO ACTION | I13: fk_reportes_ejecu_28
A14: cargas_entrada_raanariba | B14: cargas_entrada_id | C14: validaciones_entrada_raanariba | D14: cargas_entrada_id | E14: 0..N | F14: 1 | G14: No | H14: NO ACTION | I14: fk_validaciones_e_1
A15: carreras_raanariba | B15: carreras_id | C15: mallas_curriculares_raanariba | D15: carreras_id | E15: 0..N | F15: 1 | G15: No | H15: NO ACTION | I15: fk_mallas_curricu_34
A16: docentes_raanariba | B16: docentes_id | C16: docentes_secciones_raanariba | D16: docentes_id | E16: 0..N | F16: 1 | G16: No | H16: NO ACTION | I16: fk_docentes_secci_39
A17: indicadores_estadisticos_raanariba | B17: indicadores_estadisticos_id | C17: reportes_indicadores_raanariba | D17: indicadores_estadisticos_id | E17: 0..N | F17: 1 | G17: No | H17: NO ACTION | I17: fk_reportes_indic_42
... A52: usuarios_raanariba | B52: usuarios_id | C52: usuarios_roles_raanariba | D52: usuarios_id | E52: 0..N | F52: 1 | G52: No | H52: NO ACTION | I52: fk_usuarios_roles_16

Sheet Claves
A2: Claves primarias y únicas
A4: Tabla | B4: Tipo | C4: Nombre de restricción | D4: Campos de la clave | E4: Alcance de unicidad
A5: alumnos_mallas_raanariba | B5: PK | C5: pk_alumnos_mallas_0 | D5: alumnos_mallas_id | E5: Unicidad individual.
A6: alumnos_mallas_raanariba | B6: UK | C6: uk_alumnos_mallas_1 | D6: alumnos_id, mallas_curriculares_id | E6: Compuesta: la unicidad corresponde al conjunto.
A7: alumnos_raanariba | B7: PK | C7: alumnos_pk | D7: alumnos_id | E7: Unicidad individual.
A8: alumnos_raanariba | B8: UK | C8: alumnos_numero_cuenta_uk | D8: numero_cuenta | E8: Unicidad individual.
A9: alumnos_raanariba | B9: UK | C9: uk_alumnos_2 | D9: persona_id | E9: Unicidad individual.
A10: asignaturas_raanariba | B10: PK | C10: asignaturas_pk | D10: asignaturas_id | E10: Unicidad individual.
A11: asignaturas_raanariba | B11: UK | C11: asignaturas_codigo_asignatura_uk | D11: codigo_asignatura | E11: Unicidad individual.
A12: auditoria_eventos_raanariba | B12: PK | C12: auditoria_eventos_pk | D12: auditoria_eventos_id | E12: Unicidad individual.
A13: aulas_raanariba | B13: PK | C13: aulas_pk | D13: aulas_id | E13: Unicidad individual.
A14: aulas_raanariba | B14: UK | C14: aulas_codigo_aula_uk | D14: codigo_aula | E14: Unicidad individual.
A15: bitacora_operaciones_raanariba | B15: PK | C15: bitacora_operaciones_pk | D15: bitacora_operaciones_id | E15: Unicidad individual.
... A66: validaciones_entrada_raanariba | B66: PK | C66: validaciones_entrada_pk | D66: validaciones_entrada_id | E66: Unicidad individual.
